Workbook
Name Treasury_API_link: Data_Link!$A$1:$A$93942

Sheet README
B2: TREASURY & LIQUIDITY MANAGEMENT MODEL
B3: Enterprise Liquidity Monitoring & 13-Week Cash Forecast
B5: MODEL PURPOSE
B6: This workbook provides enterprise-grade treasury and liquidity management for corporate finance teams.
B7: Key capabilities include:
B8: • Daily liquidity visibility across all bank accounts and legal entities
B9: • Multi-currency cash positioning with automatic FX translation
B10: • 13-week rolling cash forecast with scenario analysis
B11: • FX exposure monitoring and sensitivity testing
B12: • Interest rate sensitivity analysis
B13: • Liquidity buffer threshold monitoring and breach alerts
B15: DATA SOURCES
B16: Source | C16: Connection Type | D16: Refresh Frequency | E16: Status
B17: Bank Balances | C17: SQL / Power Query | D17: Daily | E17: ⏳ Pending Connection
B18: FX Rates | C18: API / Power Query | D18: Real-time | E18: ⏳ Pending Connection
B19: Interest Rates | C19: Bloomberg / API | D19: Daily | E19: ⏳ Pending Connection
B20: Cash Forecast | C20: FP&A System | D20: Weekly | E20: ⏳ Pending Connection
B21: Entity Master | C21: ERP System | D21: Monthly | E21: ⏳ Pending Connection
B23: REFRESH EXPECTATIONS
B24: • Cash Balances: Updated daily by 9:00 AM local time
B25: • FX Rates: Updated real-time during market hours
B26: • 13-Week Forecast: Refreshed weekly on Monday
B27: • Dashboard: Auto-calculates on data refresh
B29: COLOR LEGEND
B30: ■ BLUE | C30: Input cells - manually entered or imported data
B31: ■ BLACK | C31: Calculated cells - formulas referencing other cells
B32: ■ GREEN | C32: Output / KPI cells - cross-sheet references and key metrics
B34: ASSUMPTIONS GOVERNANCE
B35: • All model assumptions are centralized in the 'Global_Assumptions' sheet
B36: • Changes to assumptions require Treasury Manager approval
B37: • Assumption changes must be documented with date and rationale
B38: • Quarterly review of all assumptions required
B40: SHEET NAVIGATION
B41: Sheet | C41: Purpose | D41: Type
B42: Global_Assumptions | C42: Model parameters and assumptions | D42: INPUT
B43: Date_Calendar | C43: Date reference table (18+ months) | D43: REFERENCE
B44: Cash_Balances_Actuals | C44: Daily cash balances by entity/account | D44: DATA
B45: FX_Rates | C45: Currency exchange rates | D45: DATA
B46: Interest_Rates | C46: Interest rate curves | D46: DATA
B47: Cash_Inflows | C47: Forecasted cash inflows by category | D47: FORECAST
...

Sheet Dashboard
B2: TREASURY & LIQUIDITY DASHBOARD | H2: Last Updated: | I2: =NOW() -> 46002.873
B3: Executive Summary
B5: LIQUIDITY STATUS
B6: Overall Status: | C6: {=Liquidity_Metrics!C30} -> ACTION REQUIRED
B7: Tests Passed: | C7: {=Liquidity_Metrics!C27} -> 4 | D7: of 6
B9: TOTAL CASH POSITION | E9: MINIMUM LIQUIDITY BUFFER | H9: BUFFER SURPLUS
B10: {=Liquidity_Metrics!C7} -> 132028400 | E10: =Global_Assumptions!C31 -> 50000000 | H10: =B10-E10 -> 82028400
B12: 13W ENDING CASH | E12: WEEKS OF COVERAGE | H12: FX RISK (10% STRESS)
B13: {=Liquidity_Metrics!C17} -> 134451060 | E13: {=Liquidity_Metrics!C9} -> 2.8397376 | F13: weeks | H13: {=Liquidity_Metrics!C12} -> 4232840
B15: 13-WEEK CASH FORECAST (USD Millions)
C16: Wk 0 | D16: Wk 1 | E16: Wk 2 | F16: Wk 3 | G16: Wk 4 | H16: Wk 5 | I16: Wk 6 | J16: Wk 7 | K16: Wk 8 | L16: Wk 9 | M16: Wk 10 | N16: Wk 11 | O16: Wk 12 | P16: Wk 13
B17: Ending Cash | C17: ='13W_Cash_Forecast'!C18/1000000 -> 89.7 | D17: ='13W_Cash_Forecast'!D18/1000000 -> 96.19666 | E17: ='13W_Cash_Forecast'!E18/1000000 -> 95.99348 | F17: ='13W_Cash_Forecast'!F18/1000000 -> 105.13376 | G17: ='13W_Cash_Forecast'!G18/1000000 -> 99.680544 | H17: ='13W_Cash_Forecast'!H18/1000000 -> 105.53254 | I17: ='13W_Cash_Forecast'!I18/1000000 -> 106.8272 | J17: ='13W_Cash_Forecast'!J18/1000000 -> 115.32282 | ... P17: ='13W_Cash_Forecast'!P18/1000000 -> 134.45106
B18: Net Movement | C18: ='13W_Cash_Forecast'!C17/1000000 -> 0 | D18: ='13W_Cash_Forecast'!D17/1000000 -> 6.49666 | E18: ='13W_Cash_Forecast'!E17/1000000 -> -0.20318 | F18: ='13W_Cash_Forecast'!F17/1000000 -> 9.140284 | G18: ='13W_Cash_Forecast'!G17/1000000 -> -5.45322 | H18: ='13W_Cash_Forecast'!H17/1000000 -> 5.851996 | I18: ='13W_Cash_Forecast'!I17/1000000 -> 1.29466 | J18: ='13W_Cash_Forecast'!J17/1000000 -> 8.49562 | ... P18: ='13W_Cash_Forecast'!P17/1000000 -> 6.49666
B19: Min Buffer | C19: =Global_Assumptions!$C$31/1000000 -> 50 | D19: =Global_Assumptions!$C$31/1000000 -> 50 | E19: =Global_Assumptions!$C$31/1000000 -> 50 | F19: =Global_Assumptions!$C$31/1000000 -> 50 | G19: =Global_Assumptions!$C$31/1000000 -> 50 | H19: =Global_Assumptions!$C$31/1000000 -> 50 | I19: =Global_Assumptions!$C$31/1000000 -> 50 | J19: =Global_Assumptions!$C$31/1000000 -> 50 | ... P19: =Global_Assumptions!$C$31/1000000 -> 50
B21: CASH BY CURRENCY | F21: 13-WEEK CASH FLOWS | I21: KEY RISK INDICATORS
B22: Currency | C22: Amount (USD) | D22: % of Total | F22: Category | G22: Amount | I22: Risk | J22: Status
B23: USD | C23: {=FX_Exposure!E7} -> 89700000 | D23: {=FX_Exposure!F7} -> 0.67939928 | F23: Total Inflows | G23: {=Liquidity_Metrics!C20} -> 649162260 | I23: Liquidity Buffer | J23: {=Liquidity_Metrics!E7} -> PASS
B24: EUR | C24: {=FX_Exposure!E8} -> 18960000 | D24: {=FX_Exposure!F8} -> 0.14360547 | F24: Total Outflows | G24: {=Liquidity_Metrics!C21} -> 604411200 | I24: Min Cash Test | J24: {=Liquidity_Metrics!E8} -> PASS
B25: GBP | C25: {=FX_Exposure!E9} -> 10216800 | D25: {=FX_Exposure!F9} -> 0.077383351 | F25: Net Cash Flow | G25: =G23-G24 -> 44751060 | I25: FX Concentration | J25: {=Liquidity_Metrics!E11} -> FAIL
B26: SGD | C26: {=FX_Exposure!E10} -> 13151600 | D26: {=FX_Exposure!F10} -> 0.099611902 | I26: FX Risk Level | J26: {=Liquidity_Metrics!E12} -> PASS
B27: Total | C27: {=FX_Exposure!E11} -> 132028400 | D27: 1

Sheet Global_Assumptions
B2: GLOBAL ASSUMPTIONS
B3: All model parameters and assumptions are centralized here
A5: x | B5: MODEL PARAMETERS
B6: Parameter | C6: Value | D6: Description
B7: Base Currency | C7: USD | D7: Reporting currency for all consolidated views
B8: Forecast Start Date | C8: =TODAY() -> 46002 | D8: Dynamic start date for forecast period
B9: Number of Forecast Weeks | C9: 13 | D9: Rolling forecast horizon (typically 13 weeks)
B10: Day Count Convention | C10: ACT/360 | D10: Interest calculation day count basis
B11: FX Translation Method | C11: Spot | D11: Spot rate or average rate for FX translation
B12: Interest Compounding | C12: Daily | D12: Compounding frequency for yield calculations
B13: Fiscal Year Start Month | C13: 1 | D13: Month number for fiscal year start (1=January)
A15: x | B15: INTEREST RATE ASSUMPTIONS
B16: Rate Type | C16: Current Rate | D16: Forecast Rate | E16: Source
B17: SOFR (Overnight) | C17: 0.0525 | D17: 0.05 | E17: Federal Reserve
B18: Fed Funds Rate | C18: 0.055 | D18: 0.0525 | E18: Federal Reserve
B19: 3-Month T-Bill | C19: 0.052 | D19: 0.05 | E19: Treasury Direct
B20: Prime Rate | C20: 0.085 | D20: 0.0825 | E20: WSJ Prime Rate
A22: x | B22: FX STRESS ASSUMPTIONS
B23: Scenario | C23: FX Shock % | D23: Description
B24: Base Case | C24: 0 | D24: No FX movement
B25: Mild Stress | C25: -0.01 | D25: 1% adverse FX movement
B26: Moderate Stress | C26: -0.05 | D26: 5% adverse FX movement
B27: Severe Stress | C27: -0.1 | D27: 10% adverse FX movement
A29: x | B29: LIQUIDITY THRESHOLDS
B30: Metric | C30: Threshold | D30: Action
B31: Minimum Liquidity Buffer | C31: 50000000 | D31: Escalate to CFO if breached
B32: Target Liquidity Buffer | C32: 100000000 | D32: Optimal operating range
B33: Maximum Cash Concentration % | C33: 0.4 | D33: Max % in single bank/currency
B34: Minimum Weeks of Coverage | C34: 4 | D34: Weeks of operating expenses covered
A36: x | B36: NAMED RANGE REFERENCES
B37: Use these cell references in formulas throughout the model:
B38: Reference | C38: Cell | D38: Current Value
B39: Base_Currency | C39: C7 | D39: {=C7} -> USD
B40: Forecast_Start | C40: C8 | D40: =C8 -> 46002
B41: Forecast_Weeks | C41: C9 | D41: {=C9} -> 13
B42: Min_Liquidity | C42: C31 | D42: {=C31} -> 50000000
B43: Target_Liquidity | C43: C32 | D43: {=C32} -> 100000000

Sheet Cash_Balances_Actuals
B2: CASH BALANCES (ACTUALS)
B3: Data connected via SQL / POWER QUERY
B5: Data Source: | C5: [Treasury Management System / Bank API - Currently Sample Data]
B6: Refresh Frequency: | C6: Daily at 9:00 AM
B7: Last Refresh: | C7: [AUTO-TIMESTAMP]
A9: x | B9: Date | C9: Legal Entity | D9: Entity Code | E9: Bank Name | F9: Account Number | G9: Account Type | H9: Currency | I9: Opening Balance | J9: Ending Balance | K9: Net Change
B10: 2025-12-09 | C10: Stripe US | D10: US001 | E10: JPMorgan Chase | F10: ****1234 | G10: Operating | H10: USD | I10: 25000000 | J10: 24500000 | K10: =J10-I10 -> -500000
B11: 2025-12-09 | C11: Stripe 2 US | D11: US001 | E11: Bank of America | F11: ****5678 | G11: Operating | H11: USD | I11: 15000000 | J11: 15200000 | K11: =J11-I11 -> 200000
B12: 2025-12-09 | C12: Stripe 3 US | D12: US001 | E12: Wells Fargo | F12: ****9012 | G12: Reserve | H12: USD | I12: 50000000 | J12: 50000000 | K12: =J12-I12 -> 0
B13: 2025-12-09 | C13: Stripe UK | D13: UK001 | E13: Barclays | F13: ****3456 | G13: Operating | H13: GBP | I13: 8000000 | J13: 7800000 | K13: =J13-I13 -> -200000
B14: 2025-12-09 | C14: Stripe 2 UK | D14: UK001 | E14: HSBC | F14: ****7890 | G14: Operating | H14: GBP | I14: 5000000 | J14: 5100000 | K14: =J14-I14 -> 100000
B15: 2025-12-09 | C15: Stripe EU | D15: EU001 | E15: Deutsche Bank | F15: ****2345 | G15: Operating | H15: EUR | I15: 12000000 | J15: 11800000 | K15: =J15-I15 -> -200000
B16: 2025-12-09 | C16: Stripe 2 EU | D16: EU001 | E16: BNP Paribas | F16: ****6789 | G16: Operating | H16: EUR | I16: 8000000 | J16: 8200000 | K16: =J16-I16 -> 200000
B17: 2025-12-09 | C17: Stripe SG | D17: SG001 | E17: DBS | F17: ****0123 | G17: Operating | H17: SGD | I17: 10000000 | J17: 9800000 | K17: =J17-I17 -> -200000
A19: x | B19: SUMMARY BY CURRENCY
B20: Currency | C20: Total Opening | D20: Total Ending | E20: Net Change
B21: USD | C21: =SUMIF($H$10:$H$17,B21,$I$10:$I$17) -> 90000000 | D21: =SUMIF($H$10:$H$17,B21,$J$10:$J$17) -> 89700000 | E21: =D21-C21 -> -300000
B22: GBP | C22: =SUMIF($H$10:$H$17,B22,$I$10:$I$17) -> 13000000 | D22: =SUMIF($H$10:$H$17,B22,$J$10:$J$17) -> 12900000 | E22: =D22-C22 -> -100000
B23: EUR | C23: =SUMIF($H$10:$H$17,B23,$I$10:$I$17) -> 20000000 | D23: =SUMIF($H$10:$H$17,B23,$J$10:$J$17) -> 20000000 | E23: =D23-C23 -> 0
B24: SGD | C24: =SUMIF($H$10:$H$17,B24,$I$10:$I$17) -> 10000000 | D24: =SUMIF($H$10:$H$17,B24,$J$10:$J$17) -> 9800000 | E24: =D24-C24 -> -200000
B25: TOTAL (Local Currency) | C25: =SUM(C21:C24) -> 133000000 | D25: =SUM(D21:D24) -> 132400000 | E25: =SUM(E21:E24) -> -600000

Sheet FX_Rates
B2: FX RATES (REFERENCE DATA)
B3: Data connected via SQL / POWER QUERY
B5: Data Source: | C5: [Bloomberg / Reuters / Central Bank API]
B6: Refresh Frequency: | C6: Real-time during market hours
B7: Last Refresh: | C7: [AUTO-TIMESTAMP]
A9: x | B9: SPOT FX RATES (vs USD)
B10: Date | C10: Currency | D10: Currency Name | E10: Rate to USD | F10: USD to Currency | G10: Source
B11: 2025-12-09 | C11: USD | D11: US Dollar | E11: 1 | F11: =1/E11 -> 1 | G11: Federal Reserve
B12: 2025-12-09 | C12: EUR | D12: Euro | E12: 0.948 | F12: =1/E12 -> 1.0548523 | G12: ECB
B13: 2025-12-09 | C13: GBP | D13: British Pound | E13: 0.792 | F13: =1/E13 -> 1.2626263 | G13: Bank of England
B14: 2025-12-09 | C14: JPY | D14: Japanese Yen | E14: 151.5 | F14: =1/E14 -> 0.0066006601 | G14: Bank of Japan
B15: 2025-12-09 | C15: CHF | D15: Swiss Franc | E15: 0.885 | F15: =1/E15 -> 1.1299435 | G15: SNB
B16: 2025-12-09 | C16: CAD | D16: Canadian Dollar | E16: 1.358 | F16: =1/E16 -> 0.73637703 | G16: Bank of Canada
B17: 2025-12-09 | C17: AUD | D17: Australian Dollar | E17: 1.538 | F17: =1/E17 -> 0.65019506 | G17: RBA
B18: 2025-12-09 | C18: SGD | D18: Singapore Dollar | E18: 1.342 | F18: =1/E18 -> 0.74515648 | G18: MAS
B19: 2025-12-09 | C19: HKD | D19: Hong Kong Dollar | E19: 7.785 | F19: =1/E19 -> 0.12845215 | G19: HKMA
B20: 2025-12-09 | C20: CNY | D20: Chinese Yuan | E20: 7.245 | F20: =1/E20 -> 0.13802622 | G20: PBOC
B21: 2025-12-09 | C21: INR | D21: Indian Rupee | E21: 84.25 | F21: =1/E21 -> 0.011869436 | G21: RBI
B22: 2025-12-09 | C22: MXN | D22: Mexican Peso | E22: 17.35 | F22: =1/E22 -> 0.057636888 | G22: Banxico
A24: x | B24: HISTORICAL FX RATES (for trending)
B25: Date | C25: EUR/USD | D25: GBP/USD | E25: USD/JPY | F25: USD/SGD
B26: 2025-12-09 | C26: 0.948 | D26: 0.792 | E26: 151.5 | F26: 1.342
B27: 2025-12-08 | C27: 0.9465 | D27: 0.7905 | E27: 151.25 | F27: 1.34
B28: 2025-12-07 | C28: 0.945 | D28: 0.789 | E28: 150.8 | F28: 1.3385
B29: 2025-12-06 | C29: 0.9445 | D29: 0.7885 | E29: 150.65 | F29: 1.337
B30: 2025-12-05 | C30: 0.944 | D30: 0.788 | E30: 150.4 | F30: 1.3355
B31: 2025-12-04 | C31: 0.943 | D31: 0.787 | E31: 150.2 | F31: 1.334
B32: 2025-12-03 | C32: 0.942 | D32: 0.786 | E32: 149.95 | F32: 1.3325
B33: 2025-12-02 | C33: 0.941 | D33: 0.785 | E33: 149.7 | F33: 1.331
B34: 2025-12-01 | C34: 0.94 | D34: 0.784 | E34: 149.45 | F34: 1.3295
B35: 2025-11-30 | C35: 0.939 | D35: 0.783 | E35: 149.2 | F35: 1.328
A37: x | B37: RATE LOOKUP
B38: Use to convert target rate to USD
B39: Currency Input: | C39: EUR
B40: Rate Lookup Result: | C40: =_xlfn.XLOOKUP(C39,C11:C22,E11:E22,"Not Found") -> 0.948
B41: Sample Formula: | C41: {=_xlfn.XLOOKUP("EUR",FX_Rates!C11:C22,FX_Rates!E11:E22)} -> 0.948

Sheet Date_Calendar
B2: DATE & CALENDAR TABLE
B3: Auto-generated from Global Assumptions
B5: Forecast Start Date | C5: {=Global_Assumptions!C8} -> 46002
B6: Forecast Weeks | C6: {=Global_Assumptions!C9} -> 13
B8: Date | C8: Day of Week | D8: Week of Year | E8: Fiscal Week | F8: Month | G8: Quarter | H8: Year | I8: Of Forecast Period?
A9: x | B9: {=Global_Assumptions!C8} -> 46002 | C9: =TEXT(B9,"dddd") -> Thursday | D9: =WEEKNUM(B9) -> 50 | E9: ="FW"&TEXT(WEEKNUM(B9),"00")&"-"&YEAR(B9) -> FW50-2025 | F9: =TEXT(B9,"mmmm") -> December | G9: ="Q"&CEILING(MONTH(B9)/3,1) -> Q4 | H9: =YEAR(B9) -> 2025 | I9: =IF(B9<=$C$5+($C$6*7),"Yes","No") -> Yes
B10: =B9+1 -> 46003 | C10: =TEXT(B10,"dddd") -> Friday | D10: =WEEKNUM(B10) -> 50 | E10: ="FW"&TEXT(WEEKNUM(B10),"00")&"-"&YEAR(B10) -> FW50-2025 | F10: =TEXT(B10,"mmmm") -> December | G10: ="Q"&CEILING(MONTH(B10)/3,1) -> Q4 | H10: =YEAR(B10) -> 2025 | I10: =IF(B10<=$C$5+($C$6*7),"Yes","No") -> Yes
B11: =B10+1 -> 46004 | C11: =TEXT(B11,"dddd") -> Saturday | D11: =WEEKNUM(B11) -> 50 | E11: ="FW"&TEXT(WEEKNUM(B11),"00")&"-"&YEAR(B11) -> FW50-2025 | F11: =TEXT(B11,"mmmm") -> December | G11: ="Q"&CEILING(MONTH(B11)/3,1) -> Q4 | H11: =YEAR(B11) -> 2025 | I11: =IF(B11<=$C$5+($C$6*7),"Yes","No") -> Yes
B12: =B11+1 -> 46005 | C12: =TEXT(B12,"dddd") -> Sunday | D12: =WEEKNUM(B12) -> 51 | E12: ="FW"&TEXT(WEEKNUM(B12),"00")&"-"&YEAR(B12) -> FW51-2025 | F12: =TEXT(B12,"mmmm") -> December | G12: ="Q"&CEILING(MONTH(B12)/3,1) -> Q4 | H12: =YEAR(B12) -> 2025 | I12: =IF(B12<=$C$5+($C$6*7),"Yes","No") -> Yes
B13: =B12+1 -> 46006 | C13: =TEXT(B13,"dddd") -> Monday | D13: =WEEKNUM(B13) -> 51 | E13: ="FW"&TEXT(WEEKNUM(B13),"00")&"-"&YEAR(B13) -> FW51-2025 | F13: =TEXT(B13,"mmmm") -> December | G13: ="Q"&CEILING(MONTH(B13)/3,1) -> Q4 | H13: =YEAR(B13) -> 2025 | I13: =IF(B13<=$C$5+($C$6*7),"Yes","No") -> Yes
B14: =B13+1 -> 46007 | C14: =TEXT(B14,"dddd") -> Tuesday | D14: =WEEKNUM(B14) -> 51 | E14: ="FW"&TEXT(WEEKNUM(B14),"00")&"-"&YEAR(B14) -> FW51-2025 | F14: =TEXT(B14,"mmmm") -> December | G14: ="Q"&CEILING(MONTH(B14)/3,1) -> Q4 | H14: =YEAR(B14) -> 2025 | I14: =IF(B14<=$C$5+($C$6*7),"Yes","No") -> Yes
B15: =B14+1 -> 46008 | C15: =TEXT(B15,"dddd") -> Wednesday | D15: =WEEKNUM(B15) -> 51 | E15: ="FW"&TEXT(WEEKNUM(B15),"00")&"-"&YEAR(B15) -> FW51-2025 | F15: =TEXT(B15,"mmmm") -> December | G15: ="Q"&CEILING(MONTH(B15)/3,1) -> Q4 | H15: =YEAR(B15) -> 2025 | I15: =IF(B15<=$C$5+($C$6*7),"Yes","No") -> Yes
A16: x | B16: =B15+1 -> 46009 | C16: =TEXT(B16,"dddd") -> Thursday | D16: =WEEKNUM(B16) -> 51 | E16: ="FW"&TEXT(WEEKNUM(B16),"00")&"-"&YEAR(B16) -> FW51-2025 | F16: =TEXT(B16,"mmmm") -> December | G16: ="Q"&CEILING(MONTH(B16)/3,1) -> Q4 | H16: =YEAR(B16) -> 2025 | I16: =IF(B16<=$C$5+($C$6*7),"Yes","No") -> Yes
B17: =B16+1 -> 46010 | C17: =TEXT(B17,"dddd") -> Friday | D17: =WEEKNUM(B17) -> 51 | E17: ="FW"&TEXT(WEEKNUM(B17),"00")&"-"&YEAR(B17) -> FW51-2025 | F17: =TEXT(B17,"mmmm") -> December | G17: ="Q"&CEILING(MONTH(B17)/3,1) -> Q4 | H17: =YEAR(B17) -> 2025 | I17: =IF(B17<=$C$5+($C$6*7),"Yes","No") -> Yes
B18: =B17+1 -> 46011 | C18: =TEXT(B18,"dddd") -> Saturday | D18: =WEEKNUM(B18) -> 51 | E18: ="FW"&TEXT(WEEKNUM(B18),"00")&"-"&YEAR(B18) -> FW51-2025 | F18: =TEXT(B18,"mmmm") -> December | G18: ="Q"&CEILING(MONTH(B18)/3,1) -> Q4 | H18: =YEAR(B18) -> 2025 | I18: =IF(B18<=$C$5+($C$6*7),"Yes","No") -> Yes
B19: =B18+1 -> 46012 | C19: =TEXT(B19,"dddd") -> Sunday | D19: =WEEKNUM(B19) -> 52 | E19: ="FW"&TEXT(WEEKNUM(B19),"00")&"-"&YEAR(B19) -> FW52-2025 | F19: =TEXT(B19,"mmmm") -> December | G19: ="Q"&CEILING(MONTH(B19)/3,1) -> Q4 | H19: =YEAR(B19) -> 2025 | I19: =IF(B19<=$C$5+($C$6*7),"Yes","No") -> Yes
B20: =B19+1 -> 46013 | C20: =TEXT(B20,"dddd") -> Monday | D20: =WEEKNUM(B20) -> 52 | E20: ="FW"&TEXT(WEEKNUM(B20),"00")&"-"&YEAR(B20) -> FW52-2025 | F20: =TEXT(B20,"mmmm") -> December | G20: ="Q"&CEILING(MONTH(B20)/3,1) -> Q4 | H20: =YEAR(B20) -> 2025 | I20: =IF(B20<=$C$5+($C$6*7),"Yes","No") -> Yes
B21: =B20+1 -> 46014 | C21: =TEXT(B21,"dddd") -> Tuesday | D21: =WEEKNUM(B21) -> 52 | E21: ="FW"&TEXT(WEEKNUM(B21),"00")&"-"&YEAR(B21) -> FW52-2025 | F21: =TEXT(B21,"mmmm") -> December | G21: ="Q"&CEILING(MONTH(B21)/3,1) -> Q4 | H21: =YEAR(B21) -> 2025 | I21: =IF(B21<=$C$5+($C$6*7),"Yes","No") -> Yes
B22: =B21+1 -> 46015 | C22: =TEXT(B22,"dddd") -> Wednesday | D22: =WEEKNUM(B22) -> 52 | E22: ="FW"&TEXT(WEEKNUM(B22),"00")&"-"&YEAR(B22) -> FW52-2025 | F22: =TEXT(B22,"mmmm") -> December | G22: ="Q"&CEILING(MONTH(B22)/3,1) -> Q4 | H22: =YEAR(B22) -> 2025 | I22: =IF(B22<=$C$5+($C$6*7),"Yes","No") -> Yes
A23: x | B23: =B22+1 -> 46016 | C23: =TEXT(B23,"dddd") -> Thursday | D23: =WEEKNUM(B23) -> 52 | E23: ="FW"&TEXT(WEEKNUM(B23),"00")&"-"&YEAR(B23) -> FW52-2025 | F23: =TEXT(B23,"mmmm") -> December | G23: ="Q"&CEILING(MONTH(B23)/3,1) -> Q4 | H23: =YEAR(B23) -> 2025 | I23: =IF(B23<=$C$5+($C$6*7),"Yes","No") -> Yes
B24: =B23+1 -> 46017 | C24: =TEXT(B24,"dddd") -> Friday | D24: =WEEKNUM(B24) -> 52 | E24: ="FW"&TEXT(WEEKNUM(B24),"00")&"-"&YEAR(B24) -> FW52-2025 | F24: =TEXT(B24,"mmmm") -> December | G24: ="Q"&CEILING(MONTH(B24)/3,1) -> Q4 | H24: =YEAR(B24) -> 2025 | I24: =IF(B24<=$C$5+($C$6*7),"Yes","No") -> Yes
B25: =B24+1 -> 46018 | C25: =TEXT(B25,"dddd") -> Saturday | D25: =WEEKNUM(B25) -> 52 | E25: ="FW"&TEXT(WEEKNUM(B25),"00")&"-"&YEAR(B25) -> FW52-2025 | F25: =TEXT(B25,"mmmm") -> December | G25: ="Q"&CEILING(MONTH(B25)/3,1) -> Q4 | H25: =YEAR(B25) -> 2025 | I25: =IF(B25<=$C$5+($C$6*7),"Yes","No") -> Yes
B26: =B25+1 -> 46019 | C26: =TEXT(B26,"dddd") -> Sunday | D26: =WEEKNUM(B26) -> 53 | E26: ="FW"&TEXT(WEEKNUM(B26),"00")&"-"&YEAR(B26) -> FW53-2025 | F26: =TEXT(B26,"mmmm") -> December | G26: ="Q"&CEILING(MONTH(B26)/3,1) -> Q4 | H26: =YEAR(B26) -> 2025 | I26: =IF(B26<=$C$5+($C$6*7),"Yes","No") -> Yes
B27: =B26+1 -> 46020 | C27: =TEXT(B27,"dddd") -> Monday | D27: =WEEKNUM(B27) -> 53 | E27: ="FW"&TEXT(WEEKNUM(B27),"00")&"-"&YEAR(B27) -> FW53-2025 | F27: =TEXT(B27,"mmmm") -> December | G27: ="Q"&CEILING(MONTH(B27)/3,1) -> Q4 | H27: =YEAR(B27) -> 2025 | I27: =IF(B27<=$C$5+($C$6*7),"Yes","No") -> Yes
B28: =B27+1 -> 46021 | C28: =TEXT(B28,"dddd") -> Tuesday | D28: =WEEKNUM(B28) -> 53 | E28: ="FW"&TEXT(WEEKNUM(B28),"00")&"-"&YEAR(B28) -> FW53-2025 | F28: =TEXT(B28,"mmmm") -> December | G28: ="Q"&CEILING(MONTH(B28)/3,1) -> Q4 | H28: =YEAR(B28) -> 2025 | I28: =IF(B28<=$C$5+($C$6*7),"Yes","No") -> Yes
B29: =B28+1 -> 46022 | C29: =TEXT(B29,"dddd") -> Wednesday | D29: =WEEKNUM(B29) -> 53 | E29: ="FW"&TEXT(WEEKNUM(B29),"00")&"-"&YEAR(B29) -> FW53-2025 | F29: =TEXT(B29,"mmmm") -> December | G29: ="Q"&CEILING(MONTH(B29)/3,1) -> Q4 | H29: =YEAR(B29) -> 2025 | I29: =IF(B29<=$C$5+($C$6*7),"Yes","No") -> Yes
A30: x | B30: =B29+1 -> 46023 | C30: =TEXT(B30,"dddd") -> Thursday | D30: =WEEKNUM(B30) -> 1 | E30: ="FW"&TEXT(WEEKNUM(B30),"00")&"-"&YEAR(B30) -> FW01-2026 | F30: =TEXT(B30,"mmmm") -> January | G30: ="Q"&CEILING(MONTH(B30)/3,1) -> Q1 | H30: =YEAR(B30) -> 2026 | I30: =IF(B30<=$C$5+($C$6*7),"Yes","No") -> Yes
B31: =B30+1 -> 46024 | C31: =TEXT(B31,"dddd") -> Friday | D31: =WEEKNUM(B31) -> 1 | E31: ="FW"&TEXT(WEEKNUM(B31),"00")&"-"&YEAR(B31) -> FW01-2026 | F31: =TEXT(B31,"mmmm") -> January | G31: ="Q"&CEILING(MONTH(B31)/3,1) -> Q1 | H31: =YEAR(B31) -> 2026 | I31: =IF(B31<=$C$5+($C$6*7),"Yes","No") -> Yes
B32: =B31+1 -> 46025 | C32: =TEXT(B32,"dddd") -> Saturday | D32: =WEEKNUM(B32) -> 1 | E32: ="FW"&TEXT(WEEKNUM(B32),"00")&"-"&YEAR(B32) -> FW01-2026 | F32: =TEXT(B32,"mmmm") -> January | G32: ="Q"&CEILING(MONTH(B32)/3,1) -> Q1 | H32: =YEAR(B32) -> 2026 | I32: =IF(B32<=$C$5+($C$6*7),"Yes","No") -> Yes
B33: =B32+1 -> 46026 | C33: =TEXT(B33,"dddd") -> Sunday | D33: =WEEKNUM(B33) -> 2 | E33: ="FW"&TEXT(WEEKNUM(B33),"00")&"-"&YEAR(B33) -> FW02-2026 | F33: =TEXT(B33,"mmmm") -> January | G33: ="Q"&CEILING(MONTH(B33)/3,1) -> Q1 | H33: =YEAR(B33) -> 2026 | I33: =IF(B33<=$C$5+($C$6*7),"Yes","No") -> Yes
B34: =B33+1 -> 46027 | C34: =TEXT(B34,"dddd") -> Monday | D34: =WEEKNUM(B34) -> 2 | E34: ="FW"&TEXT(WEEKNUM(B34),"00")&"-"&YEAR(B34) -> FW02-2026 | F34: =TEXT(B34,"mmmm") -> January | G34: ="Q"&CEILING(MONTH(B34)/3,1) -> Q1 | H34: =YEAR(B34) -> 2026 | I34: =IF(B34<=$C$5+($C$6*7),"Yes","No") -> Yes
B35: =B34+1 -> 46028 | C35: =TEXT(B35,"dddd") -> Tuesday | D35: =WEEKNUM(B35) -> 2 | E35: ="FW"&TEXT(WEEKNUM(B35),"00")&"-"&YEAR(B35) -> FW02-2026 | F35: =TEXT(B35,"mmmm") -> January | G35: ="Q"&CEILING(MONTH(B35)/3,1) -> Q1 | H35: =YEAR(B35) -> 2026 | I35: =IF(B35<=$C$5+($C$6*7),"Yes","No") -> Yes
B36: =B35+1 -> 46029 | C36: =TEXT(B36,"dddd") -> Wednesday | D36: =WEEKNUM(B36) -> 2 | E36: ="FW"&TEXT(WEEKNUM(B36),"00")&"-"&YEAR(B36) -> FW02-2026 | F36: =TEXT(B36,"mmmm") -> January | G36: ="Q"&CEILING(MONTH(B36)/3,1) -> Q1 | H36: =YEAR(B36) -> 2026 | I36: =IF(B36<=$C$5+($C$6*7),"Yes","No") -> Yes
A37: x | B37: =B36+1 -> 46030 | C37: =TEXT(B37,"dddd") -> Thursday | D37: =WEEKNUM(B37) -> 2 | E37: ="FW"&TEXT(WEEKNUM(B37),"00")&"-"&YEAR(B37) -> FW02-2026 | F37: =TEXT(B37,"mmmm") -> January | G37: ="Q"&CEILING(MONTH(B37)/3,1) -> Q1 | H37: =YEAR(B37) -> 2026 | I37: =IF(B37<=$C$5+($C$6*7),"Yes","No") -> Yes
B38: =B37+1 -> 46031 | C38: =TEXT(B38,"dddd") -> Friday | D38: =WEEKNUM(B38) -> 2 | E38: ="FW"&TEXT(WEEKNUM(B38),"00")&"-"&YEAR(B38) -> FW02-2026 | F38: =TEXT(B38,"mmmm") -> January | G38: ="Q"&CEILING(MONTH(B38)/3,1) -> Q1 | H38: =YEAR(B38) -> 2026 | I38: =IF(B38<=$C$5+($C$6*7),"Yes","No") -> Yes
B39: =B38+1 -> 46032 | C39: =TEXT(B39,"dddd") -> Saturday | D39: =WEEKNUM(B39) -> 2 | E39: ="FW"&TEXT(WEEKNUM(B39),"00")&"-"&YEAR(B39) -> FW02-2026 | F39: =TEXT(B39,"mmmm") -> January | G39: ="Q"&CEILING(MONTH(B39)/3,1) -> Q1 | H39: =YEAR(B39) -> 2026 | I39: =IF(B39<=$C$5+($C$6*7),"Yes","No") -> Yes
B40: =B39+1 -> 46033 | C40: =TEXT(B40,"dddd") -> Sunday | D40: =WEEKNUM(B40) -> 3 | E40: ="FW"&TEXT(WEEKNUM(B40),"00")&"-"&YEAR(B40) -> FW03-2026 | F40: =TEXT(B40,"mmmm") -> January | G40: ="Q"&CEILING(MONTH(B40)/3,1) -> Q1 | H40: =YEAR(B40) -> 2026 | I40: =IF(B40<=$C$5+($C$6*7),"Yes","No") -> Yes
B41: =B40+1 -> 46034 | C41: =TEXT(B41,"dddd") -> Monday | D41: =WEEKNUM(B41) -> 3 | E41: ="FW"&TEXT(WEEKNUM(B41),"00")&"-"&YEAR(B41) -> FW03-2026 | F41: =TEXT(B41,"mmmm") -> January | G41: ="Q"&CEILING(MONTH(B41)/3,1) -> Q1 | H41: =YEAR(B41) -> 2026 | I41: =IF(B41<=$C$5+($C$6*7),"Yes","No") -> Yes
B42: =B41+1 -> 46035 | C42: =TEXT(B42,"dddd") -> Tuesday | D42: =WEEKNUM(B42) -> 3 | E42: ="FW"&TEXT(WEEKNUM(B42),"00")&"-"&YEAR(B42) -> FW03-2026 | F42: =TEXT(B42,"mmmm") -> January | G42: ="Q"&CEILING(MONTH(B42)/3,1) -> Q1 | H42: =YEAR(B42) -> 2026 | I42: =IF(B42<=$C$5+($C$6*7),"Yes","No") -> Yes
B43: =B42+1 -> 46036 | C43: =TEXT(B43,"dddd") -> Wednesday | D43: =WEEKNUM(B43) -> 3 | E43: ="FW"&TEXT(WEEKNUM(B43),"00")&"-"&YEAR(B43) -> FW03-2026 | F43: =TEXT(B43,"mmmm") -> January | G43: ="Q"&CEILING(MONTH(B43)/3,1) -> Q1 | H43: =YEAR(B43) -> 2026 | I43: =IF(B43<=$C$5+($C$6*7),"Yes","No") -> Yes
...

Sheet Liquidity_Metrics
B2: LIQUIDITY & RISK METRICS
A5: x | B5: KEY LIQUIDITY METRICS
B6: Metric | C6: Current Value | D6: Threshold | E6: Status
B7: Total Available Liquidity | C7: {=FX_Exposure!E11} -> 132028400 | D7: {=Global_Assumptions!C31} -> 50000000 | E7: =IF(C7>=D7,"PASS","FAIL") -> PASS
B8: Minimum Forecasted Cash | C8: =MIN('13W_Cash_Forecast'!C18:P18) -> 89700000 | D8: {=Global_Assumptions!C31} -> 50000000 | E8: =IF(C8>=D8,"PASS","FAIL") -> PASS
B9: Weeks of Liquidity Coverage | C9: =IFERROR(C7/(('13W_Cash_Forecast'!G7)/13),0) -> 2.8397376 | D9: {=Global_Assumptions!C34} -> 4 | E9: =IF(C9>=D9,"PASS","FAIL") -> FAIL
B10: Liquidity Buffer Utilization % | C10: =IFERROR(C7/Global_Assumptions!C32,0) -> 1.320284 | D10: >100% | E10: =IF(C10>=1,"PASS","WATCH") -> PASS
B11: Max Currency Concentration | C11: =MAX(FX_Exposure!D24:D27) -> 0.67939928 | D11: {=Global_Assumptions!C33} -> 0.4 | E11: =IF(C11<=D11,"PASS","FAIL") -> FAIL
B12: FX Risk Exposure (10% stress) | C12: {=FX_Exposure!G18} -> 4232840 | D12: =C7*0.05 -> 6601420 | E12: =IF(C12<=D12,"PASS","WATCH") -> PASS
A14: x | B14: 13-WEEK CASH TRAJECTORY SUMMARY
B15: Metric | C15: Value
B16: Starting Cash (Week 0) | C16: {='13W_Cash_Forecast'!C18} -> 89700000
B17: Ending Cash (Week 13) | C17: {='13W_Cash_Forecast'!P18} -> 134451060
B18: Net Change | C18: =C17-C16 -> 44751060
B19: Net Change % | C19: =IFERROR(C18/C16,0) -> 0.49889699
B20: Total 13W Inflows | C20: {='13W_Cash_Forecast'!G6} -> 649162260
B21: Total 13W Outflows | C21: {='13W_Cash_Forecast'!G7} -> 604411200
B22: Minimum Cash in Period | C22: =MIN('13W_Cash_Forecast'!C18:P18) -> 89700000
B23: Maximum Cash in Period | C23: =MAX('13W_Cash_Forecast'!C18:P18) -> 134451060
B24: Average Weekly Cash | C24: =AVERAGE('13W_Cash_Forecast'!C18:P18) -> 1.1140297e+08
B26: RISK SUMMARY
B27: Tests Passed: | C27: =COUNTIF(E7:E12,"PASS") -> 4
B28: Tests Failed: | C28: =COUNTIF(E7:E12,"FAIL") -> 2
B29: Watch Items: | C29: =COUNTIF(E7:E12,"WATCH") -> 0
B30: Overall Status: | C30: =IF(C28>0,"ACTION REQUIRED",IF(C29>0,"MONITOR","HEALTHY")) -> ACTION REQUIRED

Sheet Interest_Rates
B2: INTEREST RATES (REFERENCE DATA)
B3: Data connected via SQL / POWER QUERY
B5: Data Source: | C5: [Bloomberg / Federal Reserve API]
B6: Refresh Frequency: | C6: Daily
B7: Last Refresh: | C7: [AUTO-TIMESTAMP]
B9: CURRENT BENCHMARK RATES
B10: Date | C10: Rate Type | D10: Description | E10: Rate (%) | F10: Rate (Decimal) | G10: Source
B11: 2025-12-09 | C11: SOFR | D11: Secured Overnight Financing Rate | E11: 0.0525 | F11: {=E11} -> 0.0525 | G11: Federal Reserve
B12: 2025-12-09 | C12: EFFR | D12: Effective Federal Funds Rate | E12: 0.055 | F12: {=E12} -> 0.055 | G12: Federal Reserve
B13: 2025-12-09 | C13: OBFR | D13: Overnight Bank Funding Rate | E13: 0.054 | F13: {=E13} -> 0.054 | G13: Federal Reserve
B14: 2025-12-09 | C14: PRIME | D14: US Prime Rate | E14: 0.085 | F14: {=E14} -> 0.085 | G14: WSJ Prime Rate
B15: 2025-12-09 | C15: 3M_TBILL | D15: 3-Month Treasury Bill | E15: 0.052 | F15: {=E15} -> 0.052 | G15: Treasury Direct
B16: 2025-12-09 | C16: 6M_TBILL | D16: 6-Month Treasury Bill | E16: 0.0505 | F16: {=E16} -> 0.0505 | G16: Treasury Direct
B17: 2025-12-09 | C17: 1Y_TBILL | D17: 1-Year Treasury Bill | E17: 0.0485 | F17: {=E17} -> 0.0485 | G17: Treasury Direct
B18: 2025-12-09 | C18: 10Y_TSY | D18: 10-Year Treasury | E18: 0.0445 | F18: {=E18} -> 0.0445 | G18: Treasury Direct
B19: 2025-12-09 | C19: LIBOR_1M | D19: 1-Month Term SOFR | E19: 0.0528 | F19: {=E19} -> 0.0528 | G19: CME Group
B20: 2025-12-09 | C20: LIBOR_3M | D20: 3-Month Term SOFR | E20: 0.0535 | F20: {=E20} -> 0.0535 | G20: CME Group
B22: HISTORICAL SOFR RATES (for trending)
B23: Date | C23: SOFR | D23: Fed Funds | E23: 3M T-Bill | F23: Prime
B24: 2025-12-09 | C24: 0.0525 | D24: 0.055 | E24: 0.052 | F24: 0.085
B25: 2025-12-08 | C25: 0.0525 | D25: 0.055 | E25: 0.0518 | F25: 0.085
B26: 2025-12-07 | C26: 0.0523 | D26: 0.055 | E26: 0.0515 | F26: 0.085
B27: 2025-12-06 | C27: 0.0523 | D27: 0.055 | E27: 0.0512 | F27: 0.085
B28: 2025-12-05 | C28: 0.052 | D28: 0.055 | E28: 0.051 | F28: 0.085
B29: 2025-12-04 | C29: 0.052 | D29: 0.055 | E29: 0.0508 | F29: 0.085
B30: 2025-12-03 | C30: 0.0518 | D30: 0.055 | E30: 0.0505 | F30: 0.085
B31: 2025-12-02 | C31: 0.0518 | D31: 0.055 | E31: 0.0502 | F31: 0.085
B32: 2025-12-01 | C32: 0.0515 | D32: 0.055 | E32: 0.05 | F32: 0.085
B33: 2025-11-30 | C33: 0.0515 | D33: 0.055 | E33: 0.0498 | F33: 0.085
B35: YIELD CALCULATION HELPER
B36: Use for cash drag and yield estimation:
B37: Principal Amount: | C37: 100000000
B38: Investment Rate: | C38: {=E11} -> 0.0525
B39: Days Invested: | C39: 30
B40: Day Count (ACT/360): | C40: 360
B41: Estimated Interest: | C41: =C37*C38*(C39/C40) -> 437500
B42: Annualized Yield: | C42: {=C38} -> 0.0525
B44: RATE LOOKUP HELPER
B45: Rate Type Input: | C45: SOFR
B46: Rate Lookup Result: | C46: {=_xlfn.XLOOKUP(C45,C11:C20,E11:E20,"Not Found")} -> 0.0525

Sheet Cash_Inflows
B2: CASH INFLOWS (FORECAST)
B3: Data connected via SQL / POWER QUERY
B5: Data Source: | D5: [FP&A Forecast System / Revenue Model]
B6: Refresh Frequency: | D6: Weekly (Monday)
B7: Last Refresh: | D7: [AUTO-TIMESTAMP]
B9: Week # | C9: Week Start Date | D9: Week End Date | E9: Category | F9: Sub-Category | G9: Currency | H9: Amount (Local) | I9: FX Rate | J9: Amount (USD)
A10: x | B10: 1 | C10: =Global_Assumptions!$C$8+((B10-1)*7) -> 46002 | D10: =C10+6 -> 46008 | E10: Customer Collections | F10: Recurring Revenue | G10: USD | H10: 14850000 | I10: =IFERROR(_xlfn.XLOOKUP(G10,FX_Rates!$C$11:$C$22,FX_Rates!$E$11:$E$22),1) -> 1 | J10: =H10*I10 -> 14850000
B11: 1 | C11: =Global_Assumptions!$C$8+((B11-1)*7) -> 46002 | D11: =C11+6 -> 46008 | E11: Customer Collections | F11: One-time Payments | G11: USD | H11: 2970000 | I11: =IFERROR(_xlfn.XLOOKUP(G11,FX_Rates!$C$11:$C$22,FX_Rates!$E$11:$E$22),1) -> 1 | J11: =H11*I11 -> 2970000 | M11: SUMMARY BY WEEK
B12: 1 | C12: =Global_Assumptions!$C$8+((B12-1)*7) -> 46002 | D12: =C12+6 -> 46008 | E12: Settlement Inflows | F12: Merchant Settlements | G12: USD | H12: 24750000 | I12: =IFERROR(_xlfn.XLOOKUP(G12,FX_Rates!$C$11:$C$22,FX_Rates!$E$11:$E$22),1) -> 1 | J12: =H12*I12 -> 24750000 | M12: Week | N12: Total Inflows (USD)
B13: 1 | C13: =Global_Assumptions!$C$8+((B13-1)*7) -> 46002 | D13: =C13+6 -> 46008 | E13: Settlement Inflows | F13: Partner Settlements | G13: EUR | H13: 4950000 | I13: =IFERROR(_xlfn.XLOOKUP(G13,FX_Rates!$C$11:$C$22,FX_Rates!$E$11:$E$22),1) -> 0.948 | J13: =H13*I13 -> 4692600 | M13: 1 | N13: =SUMIF($B$10:$B$100,M13,$J$10:$J$100) -> 49474260
B14: 1 | C14: =Global_Assumptions!$C$8+((B14-1)*7) -> 46002 | D14: =C14+6 -> 46008 | E14: Interest Income | F14: Money Market | G14: USD | H14: 148500 | I14: =IFERROR(_xlfn.XLOOKUP(G14,FX_Rates!$C$11:$C$22,FX_Rates!$E$11:$E$22),1) -> 1 | J14: =H14*I14 -> 148500 | M14: 2 | N14: =SUMIF($B$10:$B$100,M14,$J$10:$J$100) -> 50473740
B15: 1 | C15: =Global_Assumptions!$C$8+((B15-1)*7) -> 46002 | D15: =C15+6 -> 46008 | E15: Other Inflows | F15: Tax Refunds | G15: USD | H15: 495000 | I15: =IFERROR(_xlfn.XLOOKUP(G15,FX_Rates!$C$11:$C$22,FX_Rates!$E$11:$E$22),1) -> 1 | J15: =H15*I15 -> 495000 | M15: 3 | N15: =SUMIF($B$10:$B$100,M15,$J$10:$J$100) -> 51473220
B16: 1 | C16: =Global_Assumptions!$C$8+((B16-1)*7) -> 46002 | D16: =C16+6 -> 46008 | E16: Customer Collections | F16: International Revenue | G16: GBP | H16: 1980000 | I16: =IFERROR(_xlfn.XLOOKUP(G16,FX_Rates!$C$11:$C$22,FX_Rates!$E$11:$E$22),1) -> 0.792 | J16: =H16*I16 -> 1568160 | M16: 4 | N16: =SUMIF($B$10:$B$100,M16,$J$10:$J$100) -> 48474780
A17: x | B17: 2 | C17: =Global_Assumptions!$C$8+((B17-1)*7) -> 46009 | D17: =C17+6 -> 46015 | E17: Customer Collections | F17: Recurring Revenue | G17: USD | H17: 15150000 | I17: =IFERROR(_xlfn.XLOOKUP(G17,FX_Rates!$C$11:$C$22,FX_Rates!$E$11:$E$22),1) -> 1 | J17: =H17*I17 -> 15150000 | M17: 5 | N17: =SUMIF($B$10:$B$100,M17,$J$10:$J$100) -> 49474260
B18: 2 | C18: =Global_Assumptions!$C$8+((B18-1)*7) -> 46009 | D18: =C18+6 -> 46015 | E18: Customer Collections | F18: One-time Payments | G18: USD | H18: 3030000 | I18: =IFERROR(_xlfn.XLOOKUP(G18,FX_Rates!$C$11:$C$22,FX_Rates!$E$11:$E$22),1) -> 1 | J18: =H18*I18 -> 3030000 | M18: 6 | N18: =SUMIF($B$10:$B$100,M18,$J$10:$J$100) -> 50473740
B19: 2 | C19: =Global_Assumptions!$C$8+((B19-1)*7) -> 46009 | D19: =C19+6 -> 46015 | E19: Settlement Inflows | F19: Merchant Settlements | G19: USD | H19: 25250000 | I19: =IFERROR(_xlfn.XLOOKUP(G19,FX_Rates!$C$11:$C$22,FX_Rates!$E$11:$E$22),1) -> 1 | J19: =H19*I19 -> 25250000 | M19: 7 | N19: =SUMIF($B$10:$B$100,M19,$J$10:$J$100) -> 51473220
B20: 2 | C20: =Global_Assumptions!$C$8+((B20-1)*7) -> 46009 | D20: =C20+6 -> 46015 | E20: Settlement Inflows | F20: Partner Settlements | G20: EUR | H20: 5050000 | I20: =IFERROR(_xlfn.XLOOKUP(G20,FX_Rates!$C$11:$C$22,FX_Rates!$E$11:$E$22),1) -> 0.948 | J20: =H20*I20 -> 4787400 | M20: 8 | N20: =SUMIF($B$10:$B$100,M20,$J$10:$J$100) -> 48474780
B21: 2 | C21: =Global_Assumptions!$C$8+((B21-1)*7) -> 46009 | D21: =C21+6 -> 46015 | E21: Interest Income | F21: Money Market | G21: USD | H21: 151500 | I21: =IFERROR(_xlfn.XLOOKUP(G21,FX_Rates!$C$11:$C$22,FX_Rates!$E$11:$E$22),1) -> 1 | J21: =H21*I21 -> 151500 | M21: 9 | N21: =SUMIF($B$10:$B$100,M21,$J$10:$J$100) -> 49474260
B22: 2 | C22: =Global_Assumptions!$C$8+((B22-1)*7) -> 46009 | D22: =C22+6 -> 46015 | E22: Other Inflows | F22: Tax Refunds | G22: USD | H22: 505000 | I22: =IFERROR(_xlfn.XLOOKUP(G22,FX_Rates!$C$11:$C$22,FX_Rates!$E$11:$E$22),1) -> 1 | J22: =H22*I22 -> 505000 | M22: 10 | N22: =SUMIF($B$10:$B$100,M22,$J$10:$J$100) -> 50473740
B23: 2 | C23: =Global_Assumptions!$C$8+((B23-1)*7) -> 46009 | D23: =C23+6 -> 46015 | E23: Customer Collections | F23: International Revenue | G23: GBP | H23: 2020000 | I23: =IFERROR(_xlfn.XLOOKUP(G23,FX_Rates!$C$11:$C$22,FX_Rates!$E$11:$E$22),1) -> 0.792 | J23: =H23*I23 -> 1599840 | M23: 11 | N23: =SUMIF($B$10:$B$100,M23,$J$10:$J$100) -> 51473220
A24: x | B24: 3 | C24: =Global_Assumptions!$C$8+((B24-1)*7) -> 46016 | D24: =C24+6 -> 46022 | E24: Customer Collections | F24: Recurring Revenue | G24: USD | H24: 15450000 | I24: =IFERROR(_xlfn.XLOOKUP(G24,FX_Rates!$C$11:$C$22,FX_Rates!$E$11:$E$22),1) -> 1 | J24: =H24*I24 -> 15450000 | M24: 12 | N24: =SUMIF($B$10:$B$100,M24,$J$10:$J$100) -> 48474780
B25: 3 | C25: =Global_Assumptions!$C$8+((B25-1)*7) -> 46016 | D25: =C25+6 -> 46022 | E25: Customer Collections | F25: One-time Payments | G25: USD | H25: 3090000 | I25: =IFERROR(_xlfn.XLOOKUP(G25,FX_Rates!$C$11:$C$22,FX_Rates!$E$11:$E$22),1) -> 1 | J25: =H25*I25 -> 3090000 | M25: 13 | N25: =SUMIF($B$10:$B$100,M25,$J$10:$J$100) -> 49474260
B26: 3 | C26: =Global_Assumptions!$C$8+((B26-1)*7) -> 46016 | D26: =C26+6 -> 46022 | E26: Settlement Inflows | F26: Merchant Settlements | G26: USD | H26: 25750000 | I26: =IFERROR(_xlfn.XLOOKUP(G26,FX_Rates!$C$11:$C$22,FX_Rates!$E$11:$E$22),1) -> 1 | J26: =H26*I26 -> 25750000 | M26: TOTAL | N26: =SUM(N13:N25) -> 649162260
B27: 3 | C27: =Global_Assumptions!$C$8+((B27-1)*7) -> 46016 | D27: =C27+6 -> 46022 | E27: Settlement Inflows | F27: Partner Settlements | G27: EUR | H27: 5150000 | I27: =IFERROR(_xlfn.XLOOKUP(G27,FX_Rates!$C$11:$C$22,FX_Rates!$E$11:$E$22),1) -> 0.948 | J27: =H27*I27 -> 4882200
B28: 3 | C28: =Global_Assumptions!$C$8+((B28-1)*7) -> 46016 | D28: =C28+6 -> 46022 | E28: Interest Income | F28: Money Market | G28: USD | H28: 154500 | I28: =IFERROR(_xlfn.XLOOKUP(G28,FX_Rates!$C$11:$C$22,FX_Rates!$E$11:$E$22),1) -> 1 | J28: =H28*I28 -> 154500 | M28: SUMMARY BY CATEGORY
B29: 3 | C29: =Global_Assumptions!$C$8+((B29-1)*7) -> 46016 | D29: =C29+6 -> 46022 | E29: Other Inflows | F29: Tax Refunds | G29: USD | H29: 515000 | I29: =IFERROR(_xlfn.XLOOKUP(G29,FX_Rates!$C$11:$C$22,FX_Rates!$E$11:$E$22),1) -> 1 | J29: =H29*I29 -> 515000 | M29: Category | N29: Total (USD) | O29: % of Total
B30: 3 | C30: =Global_Assumptions!$C$8+((B30-1)*7) -> 46016 | D30: =C30+6 -> 46022 | E30: Customer Collections | F30: International Revenue | G30: GBP | H30: 2060000 | I30: =IFERROR(_xlfn.XLOOKUP(G30,FX_Rates!$C$11:$C$22,FX_Rates!$E$11:$E$22),1) -> 0.792 | J30: =H30*I30 -> 1631520 | M30: Customer Collections | N30: =SUMIF($E$10:$E$100,M30,$J$10:$J$100) -> 254396160 | O30: =N30/$N$34 -> 0.39188378
A31: x | B31: 4 | C31: =Global_Assumptions!$C$8+((B31-1)*7) -> 46023 | D31: =C31+6 -> 46029 | E31: Customer Collections | F31: Recurring Revenue | G31: USD | H31: 14550000 | I31: =IFERROR(_xlfn.XLOOKUP(G31,FX_Rates!$C$11:$C$22,FX_Rates!$E$11:$E$22),1) -> 1 | J31: =H31*I31 -> 14550000 | M31: Settlement Inflows | N31: =SUMIF($E$10:$E$100,M31,$J$10:$J$100) -> 386322600 | O31: =N31/$N$34 -> 0.59510946
B32: 4 | C32: =Global_Assumptions!$C$8+((B32-1)*7) -> 46023 | D32: =C32+6 -> 46029 | E32: Customer Collections | F32: One-time Payments | G32: USD | H32: 2910000 | I32: =IFERROR(_xlfn.XLOOKUP(G32,FX_Rates!$C$11:$C$22,FX_Rates!$E$11:$E$22),1) -> 1 | J32: =H32*I32 -> 2910000 | M32: Interest Income | N32: =SUMIF($E$10:$E$100,M32,$J$10:$J$100) -> 1948500 | O32: =N32/$N$34 -> 0.0030015608
B33: 4 | C33: =Global_Assumptions!$C$8+((B33-1)*7) -> 46023 | D33: =C33+6 -> 46029 | E33: Settlement Inflows | F33: Merchant Settlements | G33: USD | H33: 24250000 | I33: =IFERROR(_xlfn.XLOOKUP(G33,FX_Rates!$C$11:$C$22,FX_Rates!$E$11:$E$22),1) -> 1 | J33: =H33*I33 -> 24250000 | M33: Other Inflows | N33: =SUMIF($E$10:$E$100,M33,$J$10:$J$100) -> 6495000 | O33: =N33/$N$34 -> 0.010005203
B34: 4 | C34: =Global_Assumptions!$C$8+((B34-1)*7) -> 46023 | D34: =C34+6 -> 46029 | E34: Settlement Inflows | F34: Partner Settlements | G34: EUR | H34: 4850000 | I34: =IFERROR(_xlfn.XLOOKUP(G34,FX_Rates!$C$11:$C$22,FX_Rates!$E$11:$E$22),1) -> 0.948 | J34: =H34*I34 -> 4597800 | M34: TOTAL | N34: =SUM(N30:N33) -> 649162260 | O34: 1
B35: 4 | C35: =Global_Assumptions!$C$8+((B35-1)*7) -> 46023 | D35: =C35+6 -> 46029 | E35: Interest Income | F35: Money Market | G35: USD | H35: 145500 | I35: =IFERROR(_xlfn.XLOOKUP(G35,FX_Rates!$C$11:$C$22,FX_Rates!$E$11:$E$22),1) -> 1 | J35: =H35*I35 -> 145500
B36: 4 | C36: =Global_Assumptions!$C$8+((B36-1)*7) -> 46023 | D36: =C36+6 -> 46029 | E36: Other Inflows | F36: Tax Refunds | G36: USD | H36: 485000 | I36: =IFERROR(_xlfn.XLOOKUP(G36,FX_Rates!$C$11:$C$22,FX_Rates!$E$11:$E$22),1) -> 1 | J36: =H36*I36 -> 485000
B37: 4 | C37: =Global_Assumptions!$C$8+((B37-1)*7) -> 46023 | D37: =C37+6 -> 46029 | E37: Customer Collections | F37: International Revenue | G37: GBP | H37: 1940000 | I37: =IFERROR(_xlfn.XLOOKUP(G37,FX_Rates!$C$11:$C$22,FX_Rates!$E$11:$E$22),1) -> 0.792 | J37: =H37*I37 -> 1536480
A38: x | B38: 5 | C38: =Global_Assumptions!$C$8+((B38-1)*7) -> 46030 | D38: =C38+6 -> 46036 | E38: Customer Collections | F38: Recurring Revenue | G38: USD | H38: 14850000 | I38: =IFERROR(_xlfn.XLOOKUP(G38,FX_Rates!$C$11:$C$22,FX_Rates!$E$11:$E$22),1) -> 1 | J38: =H38*I38 -> 14850000
B39: 5 | C39: =Global_Assumptions!$C$8+((B39-1)*7) -> 46030 | D39: =C39+6 -> 46036 | E39: Customer Collections | F39: One-time Payments | G39: USD | H39: 2970000 | I39: =IFERROR(_xlfn.XLOOKUP(G39,FX_Rates!$C$11:$C$22,FX_Rates!$E$11:$E$22),1) -> 1 | J39: =H39*I39 -> 2970000
B40: 5 | C40: =Global_Assumptions!$C$8+((B40-1)*7) -> 46030 | D40: =C40+6 -> 46036 | E40: Settlement Inflows | F40: Merchant Settlements | G40: USD | H40: 24750000 | I40: =IFERROR(_xlfn.XLOOKUP(G40,FX_Rates!$C$11:$C$22,FX_Rates!$E$11:$E$22),1) -> 1 | J40: =H40*I40 -> 24750000
B41: 5 | C41: =Global_Assumptions!$C$8+((B41-1)*7) -> 46030 | D41: =C41+6 -> 46036 | E41: Settlement Inflows | F41: Partner Settlements | G41: EUR | H41: 4950000 | I41: =IFERROR(_xlfn.XLOOKUP(G41,FX_Rates!$C$11:$C$22,FX_Rates!$E$11:$E$22),1) -> 0.948 | J41: =H41*I41 -> 4692600
B42: 5 | C42: =Global_Assumptions!$C$8+((B42-1)*7) -> 46030 | D42: =C42+6 -> 46036 | E42: Interest Income | F42: Money Market | G42: USD | H42: 148500 | I42: =IFERROR(_xlfn.XLOOKUP(G42,FX_Rates!$C$11:$C$22,FX_Rates!$E$11:$E$22),1) -> 1 | J42: =H42*I42 -> 148500
B43: 5 | C43: =Global_Assumptions!$C$8+((B43-1)*7) -> 46030 | D43: =C43+6 -> 46036 | E43: Other Inflows | F43: Tax Refunds | G43: USD | H43: 495000 | I43: =IFERROR(_xlfn.XLOOKUP(G43,FX_Rates!$C$11:$C$22,FX_Rates!$E$11:$E$22),1) -> 1 | J43: =H43*I43 -> 495000
...

Sheet Cash_Outflows
B2: CASH OUTFLOWS (FORECAST)
B3: Data connected via SQL / POWER QUERY
B5: Data Source: | D5: [FP&A Forecast System / AP System]
B6: Refresh Frequency: | D6: Weekly (Monday)
B7: Last Refresh: | D7: [AUTO-TIMESTAMP]
B9: Week # | C9: Week Start Date | D9: Week End Date | E9: Category | F9: Sub-Category | G9: Currency | H9: Amount (USD) | I9: FX Rate | J9: Amount (USD) | K9: Scenario Multiplier
A10: x | B10: 1 | C10: =Global_Assumptions!$C$8+((B10-1)*7) -> 46002 | D10: =C10+6 -> 46008 | E10: Settlements | F10: Merchant Payouts | G10: USD | H10: 20000000 | I10: =IFERROR(_xlfn.XLOOKUP(G10,FX_Rates!$C$11:$C$22,FX_Rates!$E$11:$E$22),1) -> 1 | J10: =H10*I10*K10 -> 20000000 | K10: 1
B11: 1 | C11: =Global_Assumptions!$C$8+((B11-1)*7) -> 46002 | D11: =C11+6 -> 46008 | E11: Settlements | F11: Partner Payments | G11: USD | H11: 8000000 | I11: =IFERROR(_xlfn.XLOOKUP(G11,FX_Rates!$C$11:$C$22,FX_Rates!$E$11:$E$22),1) -> 1 | J11: =H11*I11*K11 -> 8000000 | K11: 1 | N11: SUMMARY BY WEEK
B12: 1 | C12: =Global_Assumptions!$C$8+((B12-1)*7) -> 46002 | D12: =C12+6 -> 46008 | E12: Settlements | F12: International Payouts | G12: EUR | H12: 3000000 | I12: =IFERROR(_xlfn.XLOOKUP(G12,FX_Rates!$C$11:$C$22,FX_Rates!$E$11:$E$22),1) -> 0.948 | J12: =H12*I12*K12 -> 2844000 | K12: 1 | N12: Week | O12: Total Outflows (USD)
B13: 1 | C13: =Global_Assumptions!$C$8+((B13-1)*7) -> 46002 | D13: =C13+6 -> 46008 | E13: Operating Expenses | F13: Technology & Infrastructure | G13: USD | H13: 2500000 | I13: =IFERROR(_xlfn.XLOOKUP(G13,FX_Rates!$C$11:$C$22,FX_Rates!$E$11:$E$22),1) -> 1 | J13: =H13*I13*K13 -> 2500000 | K13: 1 | N13: 1 | O13: =SUMIF($B$10:$B$139,N13,$J$10:$J$139) -> 42977600
B14: 1 | C14: =Global_Assumptions!$C$8+((B14-1)*7) -> 46002 | D14: =C14+6 -> 46008 | E14: Operating Expenses | F14: Marketing | G14: USD | H14: 1500000 | I14: =IFERROR(_xlfn.XLOOKUP(G14,FX_Rates!$C$11:$C$22,FX_Rates!$E$11:$E$22),1) -> 1 | J14: =H14*I14*K14 -> 1500000 | K14: 1 | N14: 2 | O14: =SUMIF($B$10:$B$139,N14,$J$10:$J$139) -> 50676920
B15: 1 | C15: =Global_Assumptions!$C$8+((B15-1)*7) -> 46002 | D15: =C15+6 -> 46008 | E15: Operating Expenses | F15: G&A | G15: USD | H15: 1000000 | I15: =IFERROR(_xlfn.XLOOKUP(G15,FX_Rates!$C$11:$C$22,FX_Rates!$E$11:$E$22),1) -> 1 | J15: =H15*I15*K15 -> 1000000 | K15: 1 | N15: 3 | O15: =SUMIF($B$10:$B$139,N15,$J$10:$J$139) -> 42332936
B16: 1 | C16: =Global_Assumptions!$C$8+((B16-1)*7) -> 46002 | D16: =C16+6 -> 46008 | E16: Payroll | F16: US Payroll | G16: USD | H16: 4000000 | I16: =IFERROR(_xlfn.XLOOKUP(G16,FX_Rates!$C$11:$C$22,FX_Rates!$E$11:$E$22),1) -> 1 | J16: =H16*I16*K16 -> 4000000 | K16: 1 | N16: 4 | O16: =SUMIF($B$10:$B$139,N16,$J$10:$J$139) -> 53928000
B17: 1 | C17: =Global_Assumptions!$C$8+((B17-1)*7) -> 46002 | D17: =C17+6 -> 46008 | E17: Payroll | F17: International Payroll | G17: GBP | H17: 800000 | I17: =IFERROR(_xlfn.XLOOKUP(G17,FX_Rates!$C$11:$C$22,FX_Rates!$E$11:$E$22),1) -> 0.792 | J17: =H17*I17*K17 -> 633600 | K17: 1 | N17: 5 | O17: =SUMIF($B$10:$B$139,N17,$J$10:$J$139) -> 43622264
B18: 1 | C18: =Global_Assumptions!$C$8+((B18-1)*7) -> 46002 | D18: =C18+6 -> 46008 | E18: Taxes | F18: Income Tax | G18: USD | H18: 2000000 | I18: =IFERROR(_xlfn.XLOOKUP(G18,FX_Rates!$C$11:$C$22,FX_Rates!$E$11:$E$22),1) -> 1 | J18: =H18*I18*K18 -> 2000000 | K18: 1 | N18: 6 | O18: =SUMIF($B$10:$B$139,N18,$J$10:$J$139) -> 49179080
B19: 1 | C19: =Global_Assumptions!$C$8+((B19-1)*7) -> 46002 | D19: =C19+6 -> 46008 | E19: Debt Service | F19: Interest Payments | G19: USD | H19: 500000 | I19: =IFERROR(_xlfn.XLOOKUP(G19,FX_Rates!$C$11:$C$22,FX_Rates!$E$11:$E$22),1) -> 1 | J19: =H19*I19*K19 -> 500000 | K19: 1 | N19: 7 | O19: =SUMIF($B$10:$B$139,N19,$J$10:$J$139) -> 42977600
A20: x | B20: 2 | C20: =Global_Assumptions!$C$8+((B20-1)*7) -> 46009 | D20: =C20+6 -> 46015 | E20: Settlements | F20: Merchant Payouts | G20: USD | H20: 20300000 | I20: =IFERROR(_xlfn.XLOOKUP(G20,FX_Rates!$C$11:$C$22,FX_Rates!$E$11:$E$22),1) -> 1 | J20: =H20*I20*K20 -> 20300000 | K20: 1 | N20: 8 | O20: =SUMIF($B$10:$B$139,N20,$J$10:$J$139) -> 50676920
B21: 2 | C21: =Global_Assumptions!$C$8+((B21-1)*7) -> 46009 | D21: =C21+6 -> 46015 | E21: Settlements | F21: Partner Payments | G21: USD | H21: 8120000 | I21: =IFERROR(_xlfn.XLOOKUP(G21,FX_Rates!$C$11:$C$22,FX_Rates!$E$11:$E$22),1) -> 1 | J21: =H21*I21*K21 -> 8120000 | K21: 1 | N21: 9 | O21: =SUMIF($B$10:$B$139,N21,$J$10:$J$139) -> 42332936
B22: 2 | C22: =Global_Assumptions!$C$8+((B22-1)*7) -> 46009 | D22: =C22+6 -> 46015 | E22: Settlements | F22: International Payouts | G22: EUR | H22: 3045000 | I22: =IFERROR(_xlfn.XLOOKUP(G22,FX_Rates!$C$11:$C$22,FX_Rates!$E$11:$E$22),1) -> 0.948 | J22: =H22*I22*K22 -> 2886660 | K22: 1 | N22: 10 | O22: =SUMIF($B$10:$B$139,N22,$J$10:$J$139) -> 49928000
B23: 2 | C23: =Global_Assumptions!$C$8+((B23-1)*7) -> 46009 | D23: =C23+6 -> 46015 | E23: Operating Expenses | F23: Technology & Infrastructure | G23: USD | H23: 2537500 | I23: =IFERROR(_xlfn.XLOOKUP(G23,FX_Rates!$C$11:$C$22,FX_Rates!$E$11:$E$22),1) -> 1 | J23: =H23*I23*K23 -> 2537500 | K23: 1 | N23: 11 | O23: =SUMIF($B$10:$B$139,N23,$J$10:$J$139) -> 43622264
B24: 2 | C24: =Global_Assumptions!$C$8+((B24-1)*7) -> 46009 | D24: =C24+6 -> 46015 | E24: Operating Expenses | F24: Marketing | G24: USD | H24: 1522500 | I24: =IFERROR(_xlfn.XLOOKUP(G24,FX_Rates!$C$11:$C$22,FX_Rates!$E$11:$E$22),1) -> 1 | J24: =H24*I24*K24 -> 1522500 | K24: 1 | N24: 12 | O24: =SUMIF($B$10:$B$139,N24,$J$10:$J$139) -> 49179080
B25: 2 | C25: =Global_Assumptions!$C$8+((B25-1)*7) -> 46009 | D25: =C25+6 -> 46015 | E25: Operating Expenses | F25: G&A | G25: USD | H25: 1015000 | I25: =IFERROR(_xlfn.XLOOKUP(G25,FX_Rates!$C$11:$C$22,FX_Rates!$E$11:$E$22),1) -> 1 | J25: =H25*I25*K25 -> 1015000 | K25: 1 | N25: 13 | O25: =SUMIF($B$10:$B$139,N25,$J$10:$J$139) -> 42977600
B26: 2 | C26: =Global_Assumptions!$C$8+((B26-1)*7) -> 46009 | D26: =C26+6 -> 46015 | E26: Payroll | F26: US Payroll | G26: USD | H26: 10150000 | I26: =IFERROR(_xlfn.XLOOKUP(G26,FX_Rates!$C$11:$C$22,FX_Rates!$E$11:$E$22),1) -> 1 | J26: =H26*I26*K26 -> 10150000 | K26: 1 | N26: TOTAL | O26: =SUM(O13:O25) -> 604411200
B27: 2 | C27: =Global_Assumptions!$C$8+((B27-1)*7) -> 46009 | D27: =C27+6 -> 46015 | E27: Payroll | F27: International Payroll | G27: GBP | H27: 2030000 | I27: =IFERROR(_xlfn.XLOOKUP(G27,FX_Rates!$C$11:$C$22,FX_Rates!$E$11:$E$22),1) -> 0.792 | J27: =H27*I27*K27 -> 1607760 | K27: 1
B28: 2 | C28: =Global_Assumptions!$C$8+((B28-1)*7) -> 46009 | D28: =C28+6 -> 46015 | E28: Taxes | F28: Income Tax | G28: USD | H28: 2030000 | I28: =IFERROR(_xlfn.XLOOKUP(G28,FX_Rates!$C$11:$C$22,FX_Rates!$E$11:$E$22),1) -> 1 | J28: =H28*I28*K28 -> 2030000 | K28: 1 | N28: SUMMARY BY CATEGORY
B29: 2 | C29: =Global_Assumptions!$C$8+((B29-1)*7) -> 46009 | D29: =C29+6 -> 46015 | E29: Debt Service | F29: Interest Payments | G29: USD | H29: 507500 | I29: =IFERROR(_xlfn.XLOOKUP(G29,FX_Rates!$C$11:$C$22,FX_Rates!$E$11:$E$22),1) -> 1 | J29: =H29*I29*K29 -> 507500 | K29: 1 | N29: Category | O29: Total (USD) | P29: % of Total
A30: x | B30: 3 | C30: =Global_Assumptions!$C$8+((B30-1)*7) -> 46016 | D30: =C30+6 -> 46022 | E30: Settlements | F30: Merchant Payouts | G30: USD | H30: 19700000 | I30: =IFERROR(_xlfn.XLOOKUP(G30,FX_Rates!$C$11:$C$22,FX_Rates!$E$11:$E$22),1) -> 1 | J30: =H30*I30*K30 -> 19700000 | K30: 1 | N30: Settlements | O30: =SUMIF($E$10:$E$139,N30,$J$10:$J$139) -> 400972000 | P30: =O30/$O$35 -> 0.66340928
B31: 3 | C31: =Global_Assumptions!$C$8+((B31-1)*7) -> 46016 | D31: =C31+6 -> 46022 | E31: Settlements | F31: Partner Payments | G31: USD | H31: 7880000 | I31: =IFERROR(_xlfn.XLOOKUP(G31,FX_Rates!$C$11:$C$22,FX_Rates!$E$11:$E$22),1) -> 1 | J31: =H31*I31*K31 -> 7880000 | K31: 1 | N31: Operating Expenses | O31: =SUMIF($E$10:$E$139,N31,$J$10:$J$139) -> 65000000 | P31: =O31/$O$35 -> 0.10754268
B32: 3 | C32: =Global_Assumptions!$C$8+((B32-1)*7) -> 46016 | D32: =C32+6 -> 46022 | E32: Settlements | F32: International Payouts | G32: EUR | H32: 2955000 | I32: =IFERROR(_xlfn.XLOOKUP(G32,FX_Rates!$C$11:$C$22,FX_Rates!$E$11:$E$22),1) -> 0.948 | J32: =H32*I32*K32 -> 2801340 | K32: 1 | N32: Payroll | O32: =SUMIF($E$10:$E$139,N32,$J$10:$J$139) -> 101939200 | P32: =O32/$O$35 -> 0.16865869
B33: 3 | C33: =Global_Assumptions!$C$8+((B33-1)*7) -> 46016 | D33: =C33+6 -> 46022 | E33: Operating Expenses | F33: Technology & Infrastructure | G33: USD | H33: 2462500 | I33: =IFERROR(_xlfn.XLOOKUP(G33,FX_Rates!$C$11:$C$22,FX_Rates!$E$11:$E$22),1) -> 1 | J33: =H33*I33*K33 -> 2462500 | K33: 1 | N33: Taxes | O33: =SUMIF($E$10:$E$139,N33,$J$10:$J$139) -> 30000000 | P33: =O33/$O$35 -> 0.049635083
B34: 3 | C34: =Global_Assumptions!$C$8+((B34-1)*7) -> 46016 | D34: =C34+6 -> 46022 | E34: Operating Expenses | F34: Marketing | G34: USD | H34: 1477500 | I34: =IFERROR(_xlfn.XLOOKUP(G34,FX_Rates!$C$11:$C$22,FX_Rates!$E$11:$E$22),1) -> 1 | J34: =H34*I34*K34 -> 1477500 | K34: 1 | N34: Debt Service | O34: =SUMIF($E$10:$E$139,N34,$J$10:$J$139) -> 6500000 | P34: =O34/$O$35 -> 0.010754268
B35: 3 | C35: =Global_Assumptions!$C$8+((B35-1)*7) -> 46016 | D35: =C35+6 -> 46022 | E35: Operating Expenses | F35: G&A | G35: USD | H35: 985000 | I35: =IFERROR(_xlfn.XLOOKUP(G35,FX_Rates!$C$11:$C$22,FX_Rates!$E$11:$E$22),1) -> 1 | J35: =H35*I35*K35 -> 985000 | K35: 1 | N35: TOTAL | O35: =SUM(O30:O34) -> 604411200 | P35: 1
B36: 3 | C36: =Global_Assumptions!$C$8+((B36-1)*7) -> 46016 | D36: =C36+6 -> 46022 | E36: Payroll | F36: US Payroll | G36: USD | H36: 3940000 | I36: =IFERROR(_xlfn.XLOOKUP(G36,FX_Rates!$C$11:$C$22,FX_Rates!$E$11:$E$22),1) -> 1 | J36: =H36*I36*K36 -> 3940000 | K36: 1
B37: 3 | C37: =Global_Assumptions!$C$8+((B37-1)*7) -> 46016 | D37: =C37+6 -> 46022 | E37: Payroll | F37: International Payroll | G37: GBP | H37: 788000 | I37: =IFERROR(_xlfn.XLOOKUP(G37,FX_Rates!$C$11:$C$22,FX_Rates!$E$11:$E$22),1) -> 0.792 | J37: =H37*I37*K37 -> 624096 | K37: 1 | N37: SCENARIO ANALYSIS
B38: 3 | C38: =Global_Assumptions!$C$8+((B38-1)*7) -> 46016 | D38: =C38+6 -> 46022 | E38: Taxes | F38: Income Tax | G38: USD | H38: 1970000 | I38: =IFERROR(_xlfn.XLOOKUP(G38,FX_Rates!$C$11:$C$22,FX_Rates!$E$11:$E$22),1) -> 1 | J38: =H38*I38*K38 -> 1970000 | K38: 1 | N38: Adjust 'Scenario Multiplier' column (K) to stress test outflows:
B39: 3 | C39: =Global_Assumptions!$C$8+((B39-1)*7) -> 46016 | D39: =C39+6 -> 46022 | E39: Debt Service | F39: Interest Payments | G39: USD | H39: 492500 | I39: =IFERROR(_xlfn.XLOOKUP(G39,FX_Rates!$C$11:$C$22,FX_Rates!$E$11:$E$22),1) -> 1 | J39: =H39*I39*K39 -> 492500 | K39: 1 | N39: 1.00 = Base case | O39: 1.10 = 10% increase | P39: 0.90 = 10% decrease
A40: x | B40: 4 | C40: =Global_Assumptions!$C$8+((B40-1)*7) -> 46023 | D40: =C40+6 -> 46029 | E40: Settlements | F40: Merchant Payouts | G40: USD | H40: 20000000 | I40: =IFERROR(_xlfn.XLOOKUP(G40,FX_Rates!$C$11:$C$22,FX_Rates!$E$11:$E$22),1) -> 1 | J40: =H40*I40*K40 -> 20000000 | K40: 1
B41: 4 | C41: =Global_Assumptions!$C$8+((B41-1)*7) -> 46023 | D41: =C41+6 -> 46029 | E41: Settlements | F41: Partner Payments | G41: USD | H41: 8000000 | I41: =IFERROR(_xlfn.XLOOKUP(G41,FX_Rates!$C$11:$C$22,FX_Rates!$E$11:$E$22),1) -> 1 | J41: =H41*I41*K41 -> 8000000 | K41: 1
B42: 4 | C42: =Global_Assumptions!$C$8+((B42-1)*7) -> 46023 | D42: =C42+6 -> 46029 | E42: Settlements | F42: International Payouts | G42: EUR | H42: 3000000 | I42: =IFERROR(_xlfn.XLOOKUP(G42,FX_Rates!$C$11:$C$22,FX_Rates!$E$11:$E$22),1) -> 0.948 | J42: =H42*I42*K42 -> 2844000 | K42: 1
B43: 4 | C43: =Global_Assumptions!$C$8+((B43-1)*7) -> 46023 | D43: =C43+6 -> 46029 | E43: Operating Expenses | F43: Technology & Infrastructure | G43: USD | H43: 2500000 | I43: =IFERROR(_xlfn.XLOOKUP(G43,FX_Rates!$C$11:$C$22,FX_Rates!$E$11:$E$22),1) -> 1 | J43: =H43*I43*K43 -> 2500000 | K43: 1
...

Sheet 13W_Cash_Forecast
B2: 13-WEEK ROLLING CASH FORECAST
B3: Core Calculation Sheet
B5: FORECAST PARAMETERS | F5: 13 WEEK TOTAL
B6: Base Currency: | C6: {=Global_Assumptions!C7} -> USD | F6: (+) Inflows | G6: =SUM(D15:P15) -> 649162260
B7: Forecast Start: | C7: {=Global_Assumptions!C8} -> 46002 | F7: (-) Outflows | G7: =SUM(D16:P16) -> 604411200
B8: Minimum Liquidity: | C8: {=Global_Assumptions!C31} -> 50000000 | F8: (=) Net Cash | G8: =SUM(D17:P17) -> 44751060
B9: Week 0 Balance (Actual): | C9: =SUMIF(Cash_Balances_Actuals!$H$10:$H$17,"USD",Cash_Balances_Actuals!$J$10:$J$17) -> 89700000 | F9: (=) Ending Cash | G9: {=P18} -> 134451060
B11: WEEKLY CASH FORECAST
C12: Week 0 | D12: Week 1 | E12: Week 2 | F12: Week 3 | G12: Week 4 | H12: Week 5 | I12: Week 6 | J12: Week 7 | K12: Week 8 | L12: Week 9 | M12: Week 10 | N12: Week 11 | O12: Week 12 | P12: Week 13
B13: Week Ending | C13: =C7-1 -> 46001 | D13: =C7+(1*7)-1 -> 46008 | E13: =C7+(2*7)-1 -> 46015 | F13: =C7+(3*7)-1 -> 46022 | G13: =C7+(4*7)-1 -> 46029 | H13: =C7+(5*7)-1 -> 46036 | I13: =C7+(6*7)-1 -> 46043 | J13: =C7+(7*7)-1 -> 46050 | K13: =C7+(8*7)-1 -> 46057 | L13: =C7+(9*7)-1 -> 46064 | M13: =C7+(10*7)-1 -> 46071 | N13: =C7+(11*7)-1 -> 46078 | O13: =C7+(12*7)-1 -> 46085 | P13: =C7+(13*7)-1 -> 46092
B14: Opening Cash Balance | C14: =C9 -> 89700000 | D14: {=C18} -> 89700000 | E14: {=D18} -> 96196660 | F14: {=E18} -> 95993480 | G14: {=F18} -> 105133764 | H14: {=G18} -> 99680544 | I14: {=H18} -> 105532540 | J14: {=I18} -> 106827200 | K14: {=J18} -> 115322820 | ... P14: {=O18} -> 127954400
B15: (+) Total Inflows | C15: 0 | D15: =SUMIF(Cash_Inflows!$B$10:$B$100,1,Cash_Inflows!$J$10:$J$100) -> 49474260 | E15: =SUMIF(Cash_Inflows!$B$10:$B$100,2,Cash_Inflows!$J$10:$J$100) -> 50473740 | F15: =SUMIF(Cash_Inflows!$B$10:$B$100,3,Cash_Inflows!$J$10:$J$100) -> 51473220 | G15: =SUMIF(Cash_Inflows!$B$10:$B$100,4,Cash_Inflows!$J$10:$J$100) -> 48474780 | H15: =SUMIF(Cash_Inflows!$B$10:$B$100,5,Cash_Inflows!$J$10:$J$100) -> 49474260 | I15: =SUMIF(Cash_Inflows!$B$10:$B$100,6,Cash_Inflows!$J$10:$J$100) -> 50473740 | J15: =SUMIF(Cash_Inflows!$B$10:$B$100,7,Cash_Inflows!$J$10:$J$100) -> 51473220 | K15: =SUMIF(Cash_Inflows!$B$10:$B$100,8,Cash_Inflows!$J$10:$J$100) -> 48474780 | L15: =SUMIF(Cash_Inflows!$B$10:$B$100,9,Cash_Inflows!$J$10:$J$100) -> 49474260 | M15: =SUMIF(Cash_Inflows!$B$10:$B$100,10,Cash_Inflows!$J$10:$J$100) -> 50473740 | N15: =SUMIF(Cash_Inflows!$B$10:$B$100,11,Cash_Inflows!$J$10:$J$100) -> 51473220 | O15: =SUMIF(Cash_Inflows!$B$10:$B$100,12,Cash_Inflows!$J$10:$J$100) -> 48474780 | P15: =SUMIF(Cash_Inflows!$B$10:$B$100,13,Cash_Inflows!$J$10:$J$100) -> 49474260
B16: (-) Total Outflows | C16: 0 | D16: =SUMIF(Cash_Outflows!$B$10:$B$139,1,Cash_Outflows!$J$10:$J$139) -> 42977600 | E16: =SUMIF(Cash_Outflows!$B$10:$B$139,2,Cash_Outflows!$J$10:$J$139) -> 50676920 | F16: =SUMIF(Cash_Outflows!$B$10:$B$139,3,Cash_Outflows!$J$10:$J$139) -> 42332936 | G16: =SUMIF(Cash_Outflows!$B$10:$B$139,4,Cash_Outflows!$J$10:$J$139) -> 53928000 | H16: =SUMIF(Cash_Outflows!$B$10:$B$139,5,Cash_Outflows!$J$10:$J$139) -> 43622264 | I16: =SUMIF(Cash_Outflows!$B$10:$B$139,6,Cash_Outflows!$J$10:$J$139) -> 49179080 | J16: =SUMIF(Cash_Outflows!$B$10:$B$139,7,Cash_Outflows!$J$10:$J$139) -> 42977600 | K16: =SUMIF(Cash_Outflows!$B$10:$B$139,8,Cash_Outflows!$J$10:$J$139) -> 50676920 | L16: =SUMIF(Cash_Outflows!$B$10:$B$139,9,Cash_Outflows!$J$10:$J$139) -> 42332936 | M16: =SUMIF(Cash_Outflows!$B$10:$B$139,10,Cash_Outflows!$J$10:$J$139) -> 49928000 | N16: =SUMIF(Cash_Outflows!$B$10:$B$139,11,Cash_Outflows!$J$10:$J$139) -> 43622264 | O16: =SUMIF(Cash_Outflows!$B$10:$B$139,12,Cash_Outflows!$J$10:$J$139) -> 49179080 | P16: =SUMIF(Cash_Outflows!$B$10:$B$139,13,Cash_Outflows!$J$10:$J$139) -> 42977600
B17: (=) Net Cash Movement | C17: =C15-C16 -> 0 | D17: =D15-D16 -> 6496660 | E17: =E15-E16 -> -203180 | F17: =F15-F16 -> 9140284 | G17: =G15-G16 -> -5453220 | H17: =H15-H16 -> 5851996 | I17: =I15-I16 -> 1294660 | J17: =J15-J16 -> 8495620 | ... P17: =P15-P16 -> 6496660
B18: (=) Ending Cash Balance | C18: =C14+C17 -> 89700000 | D18: =D14+D17 -> 96196660 | E18: =E14+E17 -> 95993480 | F18: =F14+F17 -> 105133764 | G18: =G14+G17 -> 99680544 | H18: =H14+H17 -> 105532540 | I18: =I14+I17 -> 106827200 | J18: =J14+J17 -> 115322820 | ... P18: =P14+P17 -> 134451060
B20: Minimum Liquidity Buffer | C20: {=$C$8} -> 50000000 | D20: {=$C$8} -> 50000000 | E20: {=$C$8} -> 50000000 | F20: {=$C$8} -> 50000000 | G20: {=$C$8} -> 50000000 | H20: {=$C$8} -> 50000000 | I20: {=$C$8} -> 50000000 | J20: {=$C$8} -> 50000000 | ... P20: {=$C$8} -> 50000000
B21: Buffer Surplus/(Deficit) | C21: =C18-C20 -> 39700000 | D21: =D18-D20 -> 46196660 | E21: =E18-E20 -> 45993480 | F21: =F18-F20 -> 55133764 | G21: =G18-G20 -> 49680544 | H21: =H18-H20 -> 55532540 | I21: =I18-I20 -> 56827200 | J21: =J18-J20 -> 65322820 | ... P21: =P18-P20 -> 84451060
B22: Liquidity Test | C22: =IF(C21>=0,"PASS","FAIL") -> PASS | D22: =IF(D21>=0,"PASS","FAIL") -> PASS | E22: =IF(E21>=0,"PASS","FAIL") -> PASS | F22: =IF(F21>=0,"PASS","FAIL") -> PASS | G22: =IF(G21>=0,"PASS","FAIL") -> PASS | H22: =IF(H21>=0,"PASS","FAIL") -> PASS | I22: =IF(I21>=0,"PASS","FAIL") -> PASS | J22: =IF(J21>=0,"PASS","FAIL") -> PASS | ... P22: =IF(P21>=0,"PASS","FAIL") -> PASS

Sheet FX_Exposure
B2: FX EXPOSURE & TRANSLATION
B3: Currency Risk Analysis and Sensitity Training
B5: CURRENT FX POSITIONS (from Cash Balances)
B6: Currency | C6: Balance (Local) | D6: FX Rate | E6: Balance (USD) | F6: % of Total
B7: USD | C7: =SUMIF(Cash_Balances_Actuals!$H$10:$H$17,B7,Cash_Balances_Actuals!$J$10:$J$17) -> 89700000 | D7: =IFERROR(_xlfn.XLOOKUP(B7,FX_Rates!$C$11:$C$22,FX_Rates!$E$11:$E$22),1) -> 1 | E7: =C7*D7 -> 89700000 | F7: =E7/$E$11 -> 0.67939928
B8: EUR | C8: =SUMIF(Cash_Balances_Actuals!$H$10:$H$17,B8,Cash_Balances_Actuals!$J$10:$J$17) -> 20000000 | D8: =IFERROR(_xlfn.XLOOKUP(B8,FX_Rates!$C$11:$C$22,FX_Rates!$E$11:$E$22),1) -> 0.948 | E8: =C8*D8 -> 18960000 | F8: =E8/$E$11 -> 0.14360547
B9: GBP | C9: =SUMIF(Cash_Balances_Actuals!$H$10:$H$17,B9,Cash_Balances_Actuals!$J$10:$J$17) -> 12900000 | D9: =IFERROR(_xlfn.XLOOKUP(B9,FX_Rates!$C$11:$C$22,FX_Rates!$E$11:$E$22),1) -> 0.792 | E9: =C9*D9 -> 10216800 | F9: =E9/$E$11 -> 0.077383351
B10: SGD | C10: =SUMIF(Cash_Balances_Actuals!$H$10:$H$17,B10,Cash_Balances_Actuals!$J$10:$J$17) -> 9800000 | D10: =IFERROR(_xlfn.XLOOKUP(B10,FX_Rates!$C$11:$C$22,FX_Rates!$E$11:$E$22),1) -> 1.342 | E10: =C10*D10 -> 13151600 | F10: =E10/$E$11 -> 0.099611902
B11: TOTAL (USD) | E11: =SUM(E7:E10) -> 132028400 | F11: 1
B13: FX SENSITIVITY ANALYSIS
B14: Currency | C14: Current USD Value | D14: 1% FX Shock | E14: 5% FX Shock | F14: 10% FX Shock | G14: Max Risk (10%)
B15: EUR | C15: =SUMIF(Cash_Balances_Actuals!$H$10:$H$17,B15,Cash_Balances_Actuals!$J$10:$J$17)*_xlfn.XLOOKUP(B15,FX_Rates!$C$11:$C$22,FX_Rates!$E$11:$E$22) -> 18960000 | D15: =C15*(1+Global_Assumptions!$C$25) -> 18770400 | E15: =C15*(1+Global_Assumptions!$C$26) -> 18012000 | F15: =C15*(1+Global_Assumptions!$C$27) -> 17064000 | G15: =C15-F15 -> 1896000
B16: GBP | C16: =SUMIF(Cash_Balances_Actuals!$H$10:$H$17,B16,Cash_Balances_Actuals!$J$10:$J$17)*_xlfn.XLOOKUP(B16,FX_Rates!$C$11:$C$22,FX_Rates!$E$11:$E$22) -> 10216800 | D16: =C16*(1+Global_Assumptions!$C$25) -> 10114632 | E16: =C16*(1+Global_Assumptions!$C$26) -> 9705960 | F16: =C16*(1+Global_Assumptions!$C$27) -> 9195120 | G16: =C16-F16 -> 1021680
